<?xml version="1.0"?>
<robot name="3_dof_manipulator">

  <material name="blue"><color rgba="0 0 1 1"/></material>
  <material name="red"><color rgba="1 0 0 1"/></material>
  <material name="green"><color rgba="0 1 0 1"/></material>
  <material name="purple"><color rgba="0.5 0 0.5 1"/></material>

  <link name="base_link">
    <visual>
      <geometry><box size="0.1 0.1 0.05"/></geometry>
      <material name="blue"/>
    </visual>
    <collision>
      <geometry><box size="0.1 0.1 0.05"/></geometry>
    </collision>
    <inertial>
      <mass value="0.5"/>
      <origin xyz="0 0 0"/>
      <inertia ixx="0.0004" ixy="0.0" ixz="0.0" iyy="0.0004" iyz="0.0" izz="0.0004"/>
    </inertial>
  </link>

  <link name="link1">
    <visual>
      <geometry><box size="0.05 0.05 0.2"/></geometry>
      <material name="red"/>
    </visual>
    <collision>
      <geometry><box size="0.05 0.05 0.2"/></geometry>
    </collision>
    <inertial>
      <mass value="0.2"/>
      <origin xyz="0 0 0"/>
      <inertia ixx="0.0002" ixy="0.0" ixz="0.0" iyy="0.0002" iyz="0.0" izz="0.0002"/>
    </inertial>
  </link>

  <link name="link2">
    <visual>
      <geometry><box size="0.05 0.05 0.2"/></geometry>
      <material name="green"/>
    </visual>
    <collision>
      <geometry><box size="0.05 0.05 0.2"/></geometry>
    </collision>
    <inertial>
      <mass value="0.2"/>
      <origin xyz="0 0 0"/>
      <inertia ixx="0.0002" ixy="0.0" ixz="0.0" iyy="0.0002" iyz="0.0" izz="0.0002"/>
    </inertial>
  </link>

  <link name="end_effector">
    <visual>
      <geometry><box size="0.05 0.05 0.05"/></geometry>
      <material name="purple"/>
    </visual>
    <collision>
      <geometry><box size="0.05 0.05 0.05"/></geometry>
    </collision>
    <inertial>
      <mass value="0.1"/>
      <origin xyz="0 0 0"/>
      <inertia ixx="0.00005" ixy="0.0" ixz="0.0" iyy="0.00005" iyz="0.0" izz="0.00005"/>
    </inertial>
  </link>

  <joint name="joint1" type="revolute">
    <parent link="base_link"/>
    <child link="link1"/>
    <origin xyz="0 0 0.075" rpy="0 0 0"/>
    <axis xyz="0 0 1"/>
    <limit lower="-1.57" upper="1.57" effort="10" velocity="0.5"/>
  </joint>

  <joint name="joint2" type="revolute">
    <parent link="link1"/>
    <child link="link2"/>
    <origin xyz="0 0 0.125" rpy="0 0 0"/>
    <axis xyz="0 1 0"/>
    <limit lower="-1.57" upper="1.57" effort="10" velocity="0.5"/>
  </joint>

  <joint name="joint3" type="revolute">
    <parent link="link2"/>
    <child link="end_effector"/>
    <origin xyz="0 0 0.125" rpy="0 0 0"/>
    <axis xyz="0 1 0"/>
    <limit lower="-1.57" upper="1.57" effort="10" velocity="0.5"/>
  </joint>

  <transmission name="joint1_transmission">
    <type>transmission_interface/SimpleTransmission</type>
    <joint name="joint1">
      <hardwareInterface>hardware_interface/PositionJointInterface</hardwareInterface>
    </joint>
    <actuator name="joint1_motor">
      <mechanicalReduction>1</mechanicalReduction>
    </actuator>
  </transmission>

  <transmission name="joint2_transmission">
    <type>transmission_interface/SimpleTransmission</type>
    <joint name="joint2">
      <hardwareInterface>hardware_interface/PositionJointInterface</hardwareInterface>
    </joint>
    <actuator name="joint2_motor">
      <mechanicalReduction>1</mechanicalReduction>
    </actuator>
  </transmission>

  <transmission name="joint3_transmission">
    <type>transmission_interface/SimpleTransmission</type>
    <joint name="joint3">
      <hardwareInterface>hardware_interface/PositionJointInterface</hardwareInterface>
    </joint>
    <actuator name="joint3_motor">
      <mechanicalReduction>1</mechanicalReduction>
    </actuator>
  </transmission>

</robot>
